import logging


try:
    print('try...')
    r = 10 / 0
    print('result:', r)
except ZeroDivisionError as e:
    print('except:', e)
finally:
    print('finally...')
print('END')


print(ZeroDivisionError)

try:
    print('try...')
    r = 10 / int('a')
    print('result:', r)
except ValueError as e:
    print('ValueError:', e)
except ZeroDivisionError as e:
    print('ZeroDivisionError:', e)
finally:
    print('finally...')
print('END')



try:
    print('try...')
    r = 10 / int('2')
    print('result:', r)
except ValueError as e:
    print('ValueError:', e)
except ZeroDivisionError as e:
    print('ZeroDivisionError:', e)
else: #如果没有错误发生，可以在except语句块后面加一个else，当没有错误发生时，会自动执行else语句
    print('no error!')
finally:
    print('finally...')
print('END')


# try:
#     foo()
# except ValueError as e:
#     print('ValueError')
# except UnicodeError as e: #第二个except永远也捕获不到UnicodeError，因为UnicodeError是ValueError的子类，如果有，也被第一个except给捕获了。
#     print('UnicodeError')


# # err.py:
# def foo(s):
#     return 10 / int(s)

# def bar(s):
#     return foo(s) * 2

# def main():
#     try:
#         bar('0')
#     except Exception as e:
#         logging.exception(e)

# main()


# class FooError(ValueError):
#     pass

# def foo(s):
#     n = int(s)
#     if n==0:
#         raise FooError('invalid value: %s' % s)
#     return 10 / n

# foo('0')


def foo(s):
    n = int(s)
    if n==0:
        raise ValueError('invalid value: %s' % s)
    return 10 / n

def bar():
    try:
        foo('0')
    except ValueError as e:
        print('ValueError!')
        raise

bar()